Workbook

Sheet Data
A1: ID | B1: Names | C1: Gender | D1: Salutation | E1: Proper Name | F1: First Name | G1: Last Name | H1: Region | I1: PassingYear | J1: Price | K1: Payment Status | L1: TotalPoints | M1: Signup Device | N1: Streak | O1: Course Name | P1: DegreeCategories - DegreeCategoryId → Name | Q1: Total Collected
A2: 64576 | B2: Aarav Dutta | C2: Male | D2: =IF(C2="Male","Mr.","Ms.") -> Mr. | E2: =PROPER(D2&" " &B2) -> Mr. Aarav Dutta | F2: =IFERROR(__xludf.DUMMYFUNCTION("SPLIT(B2,"" "")"),"Aarav") -> Aarav | G2: =IFERROR(__xludf.DUMMYFUNCTION("""COMPUTED_VALUE"""),"Dutta") -> Dutta | H2: West | I2: 2022 | J2: =IF(OR(H2="North", H2="South"), 10000, 5000) -> 5000 | K2: Pending | L2: 108 | M2: Mobile | N2: 7 | O2: Competitive Coding | P2: BE / BTech - Non CS / IT | Q2: =SUMIFS(J:J, K:K, "Completed", P:P, P2) -> 430000
A3: 64578 | B3: Dev Joshi | C3: Male | D3: =IF(C3="Male","Mr.","Ms.") -> Mr. | E3: =CONCAT(D3,B3) -> Mr.Dev Joshi | F3: =IFERROR(__xludf.DUMMYFUNCTION("SPLIT(B3,"" "")"),"Dev") -> Dev | G3: =IFERROR(__xludf.DUMMYFUNCTION("""COMPUTED_VALUE"""),"Joshi") -> Joshi | H3: North | I3: 2020 | J3: =IF(OR(H3="North", H3="South"), 10000, 5000) -> 10000 | K3: Completed | L3: 23879 | M3: Mobile | N3: 40 | O3: Kickstarting Web Dev | P3: BCA / MCA | Q3: =SUMIFS(J:J, K:K, "Completed", P:P, P3) -> 400000
A4: 64580 | B4: Manya Sharma | C4: Male | D4: =IF(C4="Male","Mr.","Ms.") -> Mr. | E4: =TEXTJOIN(TRUE, A2,B2) -> Aarav Dutta | F4: =IFERROR(__xludf.DUMMYFUNCTION("SPLIT(B4,"" "")"),"Manya") -> Manya | G4: =IFERROR(__xludf.DUMMYFUNCTION("""COMPUTED_VALUE"""),"Sharma") -> Sharma | H4: West | I4: 2022 | J4: =IF(OR(H4="North", H4="South"), 10000, 5000) -> 5000 | K4: Completed | L4: 9454 | M4: Web | N4: 22 | O4: Competitive Coding | P4: BE / BTech - CS / IT | Q4: =SUMIFS(J:J, K:K, "Completed", P:P, P4) -> 910000
A5: 64582 | B5: Samarth Iyer | C5: Male | D5: =IF(C5="Male","Mr.","Ms.") -> Mr. | E5: =PROPER(D5&" " &B5) -> Mr. Samarth Iyer | F5: =IFERROR(__xludf.DUMMYFUNCTION("SPLIT(B5,"" "")"),"Samarth") -> Samarth | G5: =IFERROR(__xludf.DUMMYFUNCTION("""COMPUTED_VALUE"""),"Iyer") -> Iyer | H5: South | I5: 2019 | J5: =IF(OR(H5="North", H5="South"), 10000, 5000) -> 10000 | K5: Pending | L5: 0 | M5: Web | N5: 76 | O5: Kickstarting Web Dev | P5: BCA / MCA | Q5: =SUMIFS(J:J, K:K, "Completed", P:P, P5) -> 400000
A6: 64583 | B6: Mishka Jain | C6: Female | D6: =IF(C6="Male","Mr.","Ms.") -> Ms. | E6: =PROPER(D6&" " &B6) -> Ms. Mishka Jain | F6: =IFERROR(__xludf.DUMMYFUNCTION("SPLIT(B6,"" "")"),"Mishka") -> Mishka | G6: =IFERROR(__xludf.DUMMYFUNCTION("""COMPUTED_VALUE"""),"Jain") -> Jain | H6: North | I6: 2024 | J6: =IF(OR(H6="North", H6="South"), 10000, 5000) -> 10000 | K6: Pending | L6: 0 | M6: Web | N6: 19 | O6: Kickstarting Web Dev | P6: BCA / MCA | Q6: =SUMIFS(J:J, K:K, "Completed", P:P, P6) -> 400000
A7: 64584 | B7: Ira Naidu | C7: Female | D7: =IF(C7="Male","Mr.","Ms.") -> Ms. | E7: =PROPER(D7&" " &B7) -> Ms. Ira Naidu | F7: =IFERROR(__xludf.DUMMYFUNCTION("SPLIT(B7,"" "")"),"Ira") -> Ira | G7: =IFERROR(__xludf.DUMMYFUNCTION("""COMPUTED_VALUE"""),"Naidu") -> Naidu | H7: West | I7: 2023 | J7: =IF(OR(H7="North", H7="South"), 10000, 5000) -> 5000 | K7: Payment in Process | L7: 0 | M7: Mobile | N7: 2 | O7: Kickstarting Web Dev | P7: Non-Coding, Non Engineering | Q7: =SUMIFS(J:J, K:K, "Completed", P:P, P7) -> 635000 | U7: SUMIFS(sum_range, criteria_range1, criterion1,
A8: 64585 | B8: Aaryan Sinha | C8: Male | D8: =IF(C8="Male","Mr.","Ms.") -> Mr. | E8: =PROPER(D8&" " &B8) -> Mr. Aaryan Sinha | F8: =IFERROR(__xludf.DUMMYFUNCTION("SPLIT(B8,"" "")"),"Aaryan") -> Aaryan | G8: =IFERROR(__xludf.DUMMYFUNCTION("""COMPUTED_VALUE"""),"Sinha") -> Sinha | H8: South | I8: 2016 | J8: =IF(OR(H8="North", H8="South"), 10000, 5000) -> 10000 | K8: Completed | L8: 1618 | M8: Web | N8: 76 | O8: Data Structure and Algorithms | P8: Non-Coding, Non Engineering | Q8: =SUMIFS(J:J, K:K, "Completed", P:P, P8) -> 635000 | U8: criteria_range2, criterion2, ...)
A9: 64586 | B9: Arnav Nair | C9: Male | D9: =IF(C9="Male","Mr.","Ms.") -> Mr. | E9: =PROPER(D9&" " &B9) -> Mr. Arnav Nair | F9: =IFERROR(__xludf.DUMMYFUNCTION("SPLIT(B9,"" "")"),"Arnav") -> Arnav | G9: =IFERROR(__xludf.DUMMYFUNCTION("""COMPUTED_VALUE"""),"Nair") -> Nair | H9: North | I9: 2018 | J9: =IF(OR(H9="North", H9="South"), 10000, 5000) -> 10000 | K9: Completed | L9: 1698 | M9: Web | N9: 63 | O9: Competitive Coding | P9: BE / BTech - CS / IT | Q9: =SUMIFS(J:J, K:K, "Completed", P:P, P9) -> 910000
A10: 64588 | B10: Lavanya Pillai | C10: Female | D10: =IF(C10="Male","Mr.","Ms.") -> Ms. | E10: =PROPER(D10&" " &B10) -> Ms. Lavanya Pillai | F10: =IFERROR(__xludf.DUMMYFUNCTION("SPLIT(B10,"" "")"),"Lavanya") -> Lavanya | G10: =IFERROR(__xludf.DUMMYFUNCTION("""COMPUTED_VALUE"""),"Pillai") -> Pillai | H10: South | I10: 2025 | J10: =IF(OR(H10="North", H10="South"), 10000, 5000) -> 10000 | K10: Completed | L10: 33696 | M10: Web | N10: 59 | O10: Kickstarting Web Dev | P10: BE / BTech - CS / IT | Q10: =SUMIFS(J:J, K:K, "Completed", P:P, P10) -> 910000
A11: 64595 | B11: Aaryan Mehta | C11: Male | D11: =IF(C11="Male","Mr.","Ms.") -> Mr. | E11: =PROPER(D11&" " &B11) -> Mr. Aaryan Mehta | F11: =IFERROR(__xludf.DUMMYFUNCTION("SPLIT(B11,"" "")"),"Aaryan") -> Aaryan | G11: =IFERROR(__xludf.DUMMYFUNCTION("""COMPUTED_VALUE"""),"Mehta") -> Mehta | H11: East | I11: 2018 | J11: =IF(OR(H11="North", H11="South"), 10000, 5000) -> 5000 | K11: Pending | L11: 1026 | M11: Web | N11: 43 | O11: Competitive Coding | P11: Non-Coding, Non Engineering | Q11: =SUMIFS(J:J, K:K, "Completed", P:P, P11) -> 635000
A12: 64596 | B12: Diya Gupta | C12: Female | D12: =IF(C12="Male","Mr.","Ms.") -> Ms. | E12: =PROPER(D12&" " &B12) -> Ms. Diya Gupta | F12: =IFERROR(__xludf.DUMMYFUNCTION("SPLIT(B12,"" "")"),"Diya") -> Diya | G12: =IFERROR(__xludf.DUMMYFUNCTION("""COMPUTED_VALUE"""),"Gupta") -> Gupta | H12: West | I12: 2016 | J12: =IF(OR(H12="North", H12="South"), 10000, 5000) -> 5000 | K12: Payment in Process | L12: 0 | M12: Mobile | N12: 40 | O12: Data Structure and Algorithms | P12: BE / BTech - CS / IT | Q12: =SUMIFS(J:J, K:K, "Completed", P:P, P12) -> 910000
A13: 64599 | B13: Kian Mishra | C13: Male | D13: =IF(C13="Male","Mr.","Ms.") -> Mr. | E13: =PROPER(D13&" " &B13) -> Mr. Kian Mishra | F13: =IFERROR(__xludf.DUMMYFUNCTION("SPLIT(B13,"" "")"),"Kian") -> Kian | G13: =IFERROR(__xludf.DUMMYFUNCTION("""COMPUTED_VALUE"""),"Mishra") -> Mishra | H13: North | I13: 2025 | J13: =IF(OR(H13="North", H13="South"), 10000, 5000) -> 10000 | K13: Pending | L13: 0 | M13: Web | N13: 27 | O13: Kickstarting Web Dev | P13: Non-Coding, Non Engineering | Q13: =SUMIFS(J:J, K:K, "Completed", P:P, P13) -> 635000
A14: 64600 | B14: Ayaan Kapoor | C14: Male | D14: =IF(C14="Male","Mr.","Ms.") -> Mr. | E14: =PROPER(D14&" " &B14) -> Mr. Ayaan Kapoor | F14: =IFERROR(__xludf.DUMMYFUNCTION("SPLIT(B14,"" "")"),"Ayaan") -> Ayaan | G14: =IFERROR(__xludf.DUMMYFUNCTION("""COMPUTED_VALUE"""),"Kapoor") -> Kapoor | H14: North | I14: 2024 | J14: =IF(OR(H14="North", H14="South"), 10000, 5000) -> 10000 | K14: Pending | L14: 0 | M14: Mobile | N14: =RANDBETWEEN(0,10) -> 2 | O14: Kickstarting Web Dev | P14: BE / BTech - CS / IT | Q14: =SUMIFS(J:J, K:K, "Completed", P:P, P14) -> 910000
A15: 64601 | B15: Manya Malik | C15: Female | D15: =IF(C15="Male","Mr.","Ms.") -> Ms. | E15: =PROPER(D15&" " &B15) -> Ms. Manya Malik | F15: =IFERROR(__xludf.DUMMYFUNCTION("SPLIT(B15,"" "")"),"Manya") -> Manya | G15: =IFERROR(__xludf.DUMMYFUNCTION("""COMPUTED_VALUE"""),"Malik") -> Malik | H15: North | I15: 2021 | J15: =IF(OR(H15="North", H15="South"), 10000, 5000) -> 10000 | K15: Pending | L15: 389 | M15: Mobile | N15: 70 | O15: Kickstarting Web Dev | P15: Non-Coding, Non Engineering | Q15: =SUMIFS(J:J, K:K, "Completed", P:P, P15) -> 635000
A16: 64602 | B16: Laksh Dutta | C16: Male | D16: =IF(C16="Male","Mr.","Ms.") -> Mr. | E16: =PROPER(D16&" " &B16) -> Mr. Laksh Dutta | F16: =IFERROR(__xludf.DUMMYFUNCTION("SPLIT(B16,"" "")"),"Laksh") -> Laksh | G16: =IFERROR(__xludf.DUMMYFUNCTION("""COMPUTED_VALUE"""),"Dutta") -> Dutta | H16: North | I16: 2026 | J16: =IF(OR(H16="North", H16="South"), 10000, 5000) -> 10000 | K16: Completed | L16: 1660 | M16: Mobile | N16: 18 | O16: Data Structure and Algorithms | P16: Non-Coding, Non Engineering | Q16: =SUMIFS(J:J, K:K, "Completed", P:P, P16) -> 635000
A17: 64603 | B17: Aaradhya Sharma | C17: Female | D17: =IF(C17="Male","Mr.","Ms.") -> Ms. | E17: =PROPER(D17&" " &B17) -> Ms. Aaradhya Sharma | F17: =IFERROR(__xludf.DUMMYFUNCTION("SPLIT(B17,"" "")"),"Aaradhya") -> Aaradhya | G17: =IFERROR(__xludf.DUMMYFUNCTION("""COMPUTED_VALUE"""),"Sharma") -> Sharma | H17: East | I17: 2023 | J17: =IF(OR(H17="North", H17="South"), 10000, 5000) -> 5000 | K17: Pending | L17: 0 | M17: Mobile | N17: 50 | O17: Kickstarting Web Dev | P17: Non-Coding, Non Engineering | Q17: =SUMIFS(J:J, K:K, "Completed", P:P, P17) -> 635000
A18: 64604 | B18: Ira Joshi | C18: Female | D18: =IF(C18="Male","Mr.","Ms.") -> Ms. | E18: =PROPER(D18&" " &B18) -> Ms. Ira Joshi | F18: =IFERROR(__xludf.DUMMYFUNCTION("SPLIT(B18,"" "")"),"Ira") -> Ira | G18: =IFERROR(__xludf.DUMMYFUNCTION("""COMPUTED_VALUE"""),"Joshi") -> Joshi | H18: East | I18: 2026 | J18: =IF(OR(H18="North", H18="South"), 10000, 5000) -> 5000 | K18: Pending | L18: 250 | M18: Mobile | N18: =RANDBETWEEN(0,10) -> 7 | O18: Data Structure and Algorithms | P18: BE / BTech - CS / IT | Q18: =SUMIFS(J:J, K:K, "Completed", P:P, P18) -> 910000
A19: 64605 | B19: Samarth Nair | C19: Male | D19: =IF(C19="Male","Mr.","Ms.") -> Mr. | E19: =PROPER(D19&" " &B19) -> Mr. Samarth Nair | F19: =IFERROR(__xludf.DUMMYFUNCTION("SPLIT(B19,"" "")"),"Samarth") -> Samarth | G19: =IFERROR(__xludf.DUMMYFUNCTION("""COMPUTED_VALUE"""),"Nair") -> Nair | H19: South | I19: 2017 | J19: =IF(OR(H19="North", H19="South"), 10000, 5000) -> 10000 | K19: Completed | L19: 4902 | M19: Web | N19: 21 | O19: Competitive Coding | P19: BE / BTech - CS / IT | Q19: =SUMIFS(J:J, K:K, "Completed", P:P, P19) -> 910000
A20: 64606 | B20: Sai Singh | C20: Male | D20: =IF(C20="Male","Mr.","Ms.") -> Mr. | E20: =PROPER(D20&" " &B20) -> Mr. Sai Singh | F20: =IFERROR(__xludf.DUMMYFUNCTION("SPLIT(B20,"" "")"),"Sai") -> Sai | G20: =IFERROR(__xludf.DUMMYFUNCTION("""COMPUTED_VALUE"""),"Singh") -> Singh | H20: East | I20: 2026 | J20: =IF(OR(H20="North", H20="South"), 10000, 5000) -> 5000 | K20: Completed | L20: 2589 | M20: Mobile | N20: =RANDBETWEEN(0,10) -> 2 | O20: Data Structure and Algorithms | P20: Non-Coding, Non Engineering | Q20: =SUMIFS(J:J, K:K, "Completed", P:P, P20) -> 635000
A21: 64607 | B21: Dev Sharma | C21: Male | D21: =IF(C21="Male","Mr.","Ms.") -> Mr. | E21: =PROPER(D21&" " &B21) -> Mr. Dev Sharma | F21: =IFERROR(__xludf.DUMMYFUNCTION("SPLIT(B21,"" "")"),"Dev") -> Dev | G21: =IFERROR(__xludf.DUMMYFUNCTION("""COMPUTED_VALUE"""),"Sharma") -> Sharma | H21: North | I21: 2025 | J21: =IF(OR(H21="North", H21="South"), 10000, 5000) -> 10000 | K21: Pending | L21: 0 | M21: Mobile | N21: =RANDBETWEEN(0,10) -> 9 | O21: Kickstarting Web Dev | P21: Non-Coding, Non Engineering | Q21: =SUMIFS(J:J, K:K, "Completed", P:P, P21) -> 635000
A22: 64608 | B22: Vihaan Pillai | C22: Male | D22: =IF(C22="Male","Mr.","Ms.") -> Mr. | E22: =PROPER(D22&" " &B22) -> Mr. Vihaan Pillai | F22: =IFERROR(__xludf.DUMMYFUNCTION("SPLIT(B22,"" "")"),"Vihaan") -> Vihaan | G22: =IFERROR(__xludf.DUMMYFUNCTION("""COMPUTED_VALUE"""),"Pillai") -> Pillai | H22: North | I22: 2024 | J22: =IF(OR(H22="North", H22="South"), 10000, 5000) -> 10000 | K22: Pending | L22: 424 | M22: Mobile | N22: 54 | O22: Competitive Coding | P22: BCA / MCA | Q22: =SUMIFS(J:J, K:K, "Completed", P:P, P22) -> 400000
A23: 64609 | B23: Manya Pillai | C23: Female | D23: =IF(C23="Male","Mr.","Ms.") -> Ms. | E23: =PROPER(D23&" " &B23) -> Ms. Manya Pillai | F23: =IFERROR(__xludf.DUMMYFUNCTION("SPLIT(B23,"" "")"),"Manya") -> Manya | G23: =IFERROR(__xludf.DUMMYFUNCTION("""COMPUTED_VALUE"""),"Pillai") -> Pillai | H23: North | I23: 2021 | J23: =IF(OR(H23="North", H23="South"), 10000, 5000) -> 10000 | K23: Pending | L23: 0 | M23: Mobile | N23: 33 | O23: Kickstarting Web Dev | P23: Non-Coding, Non Engineering | Q23: =SUMIFS(J:J, K:K, "Completed", P:P, P23) -> 635000
A24: 64610 | B24: Om Thakur | C24: Male | D24: =IF(C24="Male","Mr.","Ms.") -> Mr. | E24: =PROPER(D24&" " &B24) -> Mr. Om Thakur | F24: =IFERROR(__xludf.DUMMYFUNCTION("SPLIT(B24,"" "")"),"Om") -> Om | G24: =IFERROR(__xludf.DUMMYFUNCTION("""COMPUTED_VALUE"""),"Thakur") -> Thakur | H24: North | I24: 2023 | J24: =IF(OR(H24="North", H24="South"), 10000, 5000) -> 10000 | K24: Completed | L24: 18697 | M24: Web | N24: 16 | O24: Competitive Coding | P24: Non-Coding, Non Engineering | Q24: =SUMIFS(J:J, K:K, "Completed", P:P, P24) -> 635000
A25: 64611 | B25: Naira Rao | C25: Female | D25: =IF(C25="Male","Mr.","Ms.") -> Ms. | E25: =PROPER(D25&" " &B25) -> Ms. Naira Rao | F25: =IFERROR(__xludf.DUMMYFUNCTION("SPLIT(B25,"" "")"),"Naira") -> Naira | G25: =IFERROR(__xludf.DUMMYFUNCTION("""COMPUTED_VALUE"""),"Rao") -> Rao | H25: West | I25: 2023 | J25: =IF(OR(H25="North", H25="South"), 10000, 5000) -> 5000 | K25: Pending | L25: 0 | M25: Mobile | N25: 47 | O25: Kickstarting Web Dev | P25: BE / BTech - CS / IT | Q25: =SUMIFS(J:J, K:K, "Completed", P:P, P25) -> 910000
A26: 64612 | B26: Aarohi Reddy | C26: Female | D26: =IF(C26="Male","Mr.","Ms.") -> Ms. | E26: =PROPER(D26&" " &B26) -> Ms. Aarohi Reddy | F26: =IFERROR(__xludf.DUMMYFUNCTION("SPLIT(B26,"" "")"),"Aarohi") -> Aarohi | G26: =IFERROR(__xludf.DUMMYFUNCTION("""COMPUTED_VALUE"""),"Reddy") -> Reddy | H26: North | I26: 2022 | J26: =IF(OR(H26="North", H26="South"), 10000, 5000) -> 10000 | K26: Pending | L26: 0 | M26: Mobile | N26: 65 | O26: Kickstarting Web Dev | P26: Non-Coding, Non Engineering | Q26: =SUMIFS(J:J, K:K, "Completed", P:P, P26) -> 635000
A27: 64613 | B27: Anvi Verma | C27: Female | D27: =IF(C27="Male","Mr.","Ms.") -> Ms. | E27: =PROPER(D27&" " &B27) -> Ms. Anvi Verma | F27: =IFERROR(__xludf.DUMMYFUNCTION("SPLIT(B27,"" "")"),"Anvi") -> Anvi | G27: =IFERROR(__xludf.DUMMYFUNCTION("""COMPUTED_VALUE"""),"Verma") -> Verma | H27: West | I27: 2025 | J27: =IF(OR(H27="North", H27="South"), 10000, 5000) -> 5000 | K27: Pending | L27: 0 | M27: Mobile | N27: 46 | O27: Kickstarting Web Dev | P27: BCA / MCA | Q27: =SUMIFS(J:J, K:K, "Completed", P:P, P27) -> 400000
A28: 64614 | B28: Tara Sinha | C28: Female | D28: =IF(C28="Male","Mr.","Ms.") -> Ms. | E28: =PROPER(D28&" " &B28) -> Ms. Tara Sinha | F28: =IFERROR(__xludf.DUMMYFUNCTION("SPLIT(B28,"" "")"),"Tara") -> Tara | G28: =IFERROR(__xludf.DUMMYFUNCTION("""COMPUTED_VALUE"""),"Sinha") -> Sinha | H28: South | I28: 2026 | J28: =IF(OR(H28="North", H28="South"), 10000, 5000) -> 10000 | K28: Pending | L28: 0 | M28: Mobile | N28: =RANDBETWEEN(0,10) -> 6 | O28: Kickstarting Web Dev | P28: BE / BTech - Non CS / IT | Q28: =SUMIFS(J:J, K:K, "Completed", P:P, P28) -> 430000
A29: 64618 | B29: Vihaan Jain | C29: Male | D29: =IF(C29="Male","Mr.","Ms.") -> Mr. | E29: =PROPER(D29&" " &B29) -> Mr. Vihaan Jain | F29: =IFERROR(__xludf.DUMMYFUNCTION("SPLIT(B29,"" "")"),"Vihaan") -> Vihaan | G29: =IFERROR(__xludf.DUMMYFUNCTION("""COMPUTED_VALUE"""),"Jain") -> Jain | H29: West | I29: 2023 | J29: =IF(OR(H29="North", H29="South"), 10000, 5000) -> 5000 | K29: Pending | L29: 0 | M29: Mobile | N29: 55 | O29: Kickstarting Web Dev | P29: BE / BTech - CS / IT | Q29: =SUMIFS(J:J, K:K, "Completed", P:P, P29) -> 910000
A30: 64619 | B30: Diya Sharma | C30: Female | D30: =IF(C30="Male","Mr.","Ms.") -> Ms. | E30: =PROPER(D30&" " &B30) -> Ms. Diya Sharma | F30: =IFERROR(__xludf.DUMMYFUNCTION("SPLIT(B30,"" "")"),"Diya") -> Diya | G30: =IFERROR(__xludf.DUMMYFUNCTION("""COMPUTED_VALUE"""),"Sharma") -> Sharma | H30: South | I30: 2026 | J30: =IF(OR(H30="North", H30="South"), 10000, 5000) -> 10000 | K30: Completed | L30: 12779 | M30: Mobile | N30: 75 | O30: Kickstarting Web Dev | P30: BE / BTech - CS / IT | Q30: =SUMIFS(J:J, K:K, "Completed", P:P, P30) -> 910000
A31: 64620 | B31: Vivaan Reddy | C31: Male | D31: =IF(C31="Male","Mr.","Ms.") -> Mr. | E31: =PROPER(D31&" " &B31) -> Mr. Vivaan Reddy | F31: =IFERROR(__xludf.DUMMYFUNCTION("SPLIT(B31,"" "")"),"Vivaan") -> Vivaan | G31: =IFERROR(__xludf.DUMMYFUNCTION("""COMPUTED_VALUE"""),"Reddy") -> Reddy | H31: North | I31: 2023 | J31: =IF(OR(H31="North", H31="South"), 10000, 5000) -> 10000 | K31: Pending | L31: 265 | M31: Mobile | N31: 28 | O31: Data Structure and Algorithms | P31: BE / BTech - CS / IT | Q31: =SUMIFS(J:J, K:K, "Completed", P:P, P31) -> 910000
A32: 64621 | B32: Saanvi Naidu | C32: Female | D32: =IF(C32="Male","Mr.","Ms.") -> Ms. | E32: =PROPER(D32&" " &B32) -> Ms. Saanvi Naidu | F32: =IFERROR(__xludf.DUMMYFUNCTION("SPLIT(B32,"" "")"),"Saanvi") -> Saanvi | G32: =IFERROR(__xludf.DUMMYFUNCTION("""COMPUTED_VALUE"""),"Naidu") -> Naidu | H32: East | I32: 2025 | J32: =IF(OR(H32="North", H32="South"), 10000, 5000) -> 5000 | K32: Pending | L32: 0 | M32: Mobile | N32: =RANDBETWEEN(0,10) -> 5 | O32: Kickstarting Web Dev | P32: Non-Coding, Non Engineering | Q32: =SUMIFS(J:J, K:K, "Completed", P:P, P32) -> 635000
A33: 64622 | B33: Riddhi Malik | C33: Female | D33: =IF(C33="Male","Mr.","Ms.") -> Ms. | E33: =PROPER(D33&" " &B33) -> Ms. Riddhi Malik | F33: =IFERROR(__xludf.DUMMYFUNCTION("SPLIT(B33,"" "")"),"Riddhi") -> Riddhi | G33: =IFERROR(__xludf.DUMMYFUNCTION("""COMPUTED_VALUE"""),"Malik") -> Malik | H33: North | I33: 2024 | J33: =IF(OR(H33="North", H33="South"), 10000, 5000) -> 10000 | K33: Completed | L33: 9147 | M33: Mobile | N33: 60 | O33: Kickstarting Web Dev | P33: Non-Coding, Non Engineering | Q33: =SUMIFS(J:J, K:K, "Completed", P:P, P33) -> 635000
A34: 64624 | B34: Aaryan Bhatt | C34: Male | D34: =IF(C34="Male","Mr.","Ms.") -> Mr. | E34: =PROPER(D34&" " &B34) -> Mr. Aaryan Bhatt | F34: =IFERROR(__xludf.DUMMYFUNCTION("SPLIT(B34,"" "")"),"Aaryan") -> Aaryan | G34: =IFERROR(__xludf.DUMMYFUNCTION("""COMPUTED_VALUE"""),"Bhatt") -> Bhatt | H34: East | I34: 2019 | J34: =IF(OR(H34="North", H34="South"), 10000, 5000) -> 5000 | K34: Payment in Process | L34: 0 | M34: Mobile | N34: 64 | O34: Data Structure and Algorithms | P34: Non-Coding, Non Engineering | Q34: =SUMIFS(J:J, K:K, "Completed", P:P, P34) -> 635000
A35: 64625 | B35: Charvi Bhatt | C35: Female | D35: =IF(C35="Male","Mr.","Ms.") -> Ms. | E35: =PROPER(D35&" " &B35) -> Ms. Charvi Bhatt | F35: =IFERROR(__xludf.DUMMYFUNCTION("SPLIT(B35,"" "")"),"Charvi") -> Charvi | G35: =IFERROR(__xludf.DUMMYFUNCTION("""COMPUTED_VALUE"""),"Bhatt") -> Bhatt | H35: South | I35: 2026 | J35: =IF(OR(H35="North", H35="South"), 10000, 5000) -> 10000 | K35: Completed | L35: 6964 | M35: Mobile | N35: 62 | O35: Data Structure and Algorithms | P35: Non-Coding, Non Engineering | Q35: =SUMIFS(J:J, K:K, "Completed", P:P, P35) -> 635000
A36: 64626 | B36: Aryan Nair | C36: Male | D36: =IF(C36="Male","Mr.","Ms.") -> Mr. | E36: =PROPER(D36&" " &B36) -> Mr. Aryan Nair | F36: =IFERROR(__xludf.DUMMYFUNCTION("SPLIT(B36,"" "")"),"Aryan") -> Aryan | G36: =IFERROR(__xludf.DUMMYFUNCTION("""COMPUTED_VALUE"""),"Nair") -> Nair | H36: East | I36: 2022 | J36: =IF(OR(H36="North", H36="South"), 10000, 5000) -> 5000 | K36: Completed | L36: 10827 | M36: Mobile | N36: 29 | O36: Data Structure and Algorithms | P36: BCA / MCA | Q36: =SUMIFS(J:J, K:K, "Completed", P:P, P36) -> 400000
A37: 64627 | B37: Aaryan Kumar | C37: Male | D37: =IF(C37="Male","Mr.","Ms.") -> Mr. | E37: =PROPER(D37&" " &B37) -> Mr. Aaryan Kumar | F37: =IFERROR(__xludf.DUMMYFUNCTION("SPLIT(B37,"" "")"),"Aaryan") -> Aaryan | G37: =IFERROR(__xludf.DUMMYFUNCTION("""COMPUTED_VALUE"""),"Kumar") -> Kumar | H37: West | I37: 2024 | J37: =IF(OR(H37="North", H37="South"), 10000, 5000) -> 5000 | K37: Pending | L37: 0 | M37: Mobile | N37: 49 | O37: Data Structure and Algorithms | P37: Non-Coding, Non Engineering | Q37: =SUMIFS(J:J, K:K, "Completed", P:P, P37) -> 635000
A38: 64628 | B38: Samarth Kapoor | C38: Male | D38: =IF(C38="Male","Mr.","Ms.") -> Mr. | E38: =PROPER(D38&" " &B38) -> Mr. Samarth Kapoor | F38: =IFERROR(__xludf.DUMMYFUNCTION("SPLIT(B38,"" "")"),"Samarth") -> Samarth | G38: =IFERROR(__xludf.DUMMYFUNCTION("""COMPUTED_VALUE"""),"Kapoor") -> Kapoor | H38: West | I38: 2021 | J38: =IF(OR(H38="North", H38="South"), 10000, 5000) -> 5000 | K38: Pending | L38: 0 | M38: Mobile | N38: 14 | O38: Data Structure and Algorithms | P38: BCA / MCA | Q38: =SUMIFS(J:J, K:K, "Completed", P:P, P38) -> 400000
A39: 64629 | B39: Gauri Chopra | C39: Female | D39: =IF(C39="Male","Mr.","Ms.") -> Ms. | E39: =PROPER(D39&" " &B39) -> Ms. Gauri Chopra | F39: =IFERROR(__xludf.DUMMYFUNCTION("SPLIT(B39,"" "")"),"Gauri") -> Gauri | G39: =IFERROR(__xludf.DUMMYFUNCTION("""COMPUTED_VALUE"""),"Chopra") -> Chopra | H39: West | I39: 2024 | J39: =IF(OR(H39="North", H39="South"), 10000, 5000) -> 5000 | K39: Completed | L39: 24189 | M39: Web | N39: 67 | O39: Competitive Coding | P39: BE / BTech - CS / IT | Q39: =SUMIFS(J:J, K:K, "Completed", P:P, P39) -> 910000
A40: 64630 | B40: Vivaan Singh | C40: Male | D40: =IF(C40="Male","Mr.","Ms.") -> Mr. | E40: =PROPER(D40&" " &B40) -> Mr. Vivaan Singh | F40: =IFERROR(__xludf.DUMMYFUNCTION("SPLIT(B40,"" "")"),"Vivaan") -> Vivaan | G40: =IFERROR(__xludf.DUMMYFUNCTION("""COMPUTED_VALUE"""),"Singh") -> Singh | H40: South | I40: 2018 | J40: =IF(OR(H40="North", H40="South"), 10000, 5000) -> 10000 | K40: Pending | L40: 4106 | M40: Web | N40: 54 | O40: Competitive Coding | P40: BCA / MCA | Q40: =SUMIFS(J:J, K:K, "Completed", P:P, P40) -> 400000
...

Sheet Login Issues- VLOOKUP
A1: User ID | B1: Name | C1: Region | D1: Device
A2: 64633 | B2: =VLOOKUP(A2,Data!$A$2:$P$1001, 2, FALSE) -> Laksh Kulkarni | C2: =VLOOKUP(A2,Data!$A$2:$P$1001, 8, FALSE) -> South | D2: =VLOOKUP(A2,Data!$A$2:$P$1001, 13, FALSE) -> Mobile
A3: 64634 | B3: =VLOOKUP(A3,Data!$A$2:$P$1001, 2, FALSE) -> Atharv Singh | C3: =VLOOKUP(A3,Data!$A$2:$P$1001, 8, FALSE) -> North | D3: =VLOOKUP(A3,Data!$A$2:$P$1001, 13, FALSE) -> Mobile
A4: 64972 | B4: =VLOOKUP(A4,Data!$A$2:$P$1001, 2, FALSE) -> Anaya Kumar | C4: =VLOOKUP(A4,Data!$A$2:$P$1001, 8, FALSE) -> East | D4: =VLOOKUP(A4,Data!$A$2:$P$1001, 13, FALSE) -> Mobile
A5: 64805 | B5: =VLOOKUP(A5,Data!$A$2:$P$1001, 2, FALSE) -> Tara Patel | C5: =VLOOKUP(A5,Data!$A$2:$P$1001, 8, FALSE) -> North | D5: =VLOOKUP(A5,Data!$A$2:$P$1001, 13, FALSE) -> Mobile
A6: 64637 | B6: =VLOOKUP(A6,Data!$A$2:$P$1001, 2, FALSE) -> Aarohi Gupta | C6: =VLOOKUP(A6,Data!$A$2:$P$1001, 8, FALSE) -> North | D6: =VLOOKUP(A6,Data!$A$2:$P$1001, 13, FALSE) -> Mobile
A7: 64806 | B7: =VLOOKUP(A7,Data!$A$2:$P$1001, 2, FALSE) -> Eva Verma | C7: =VLOOKUP(A7,Data!$A$2:$P$1001, 8, FALSE) -> East | D7: =VLOOKUP(A7,Data!$A$2:$P$1001, 13, FALSE) -> Mobile
A8: 64970 | B8: =VLOOKUP(A8,Data!$A$2:$P$1001, 2, FALSE) -> Anvi Dutta | C8: =VLOOKUP(A8,Data!$A$2:$P$1001, 8, FALSE) -> South | D8: =VLOOKUP(A8,Data!$A$2:$P$1001, 13, FALSE) -> Mobile
A9: 64971 | B9: =VLOOKUP(A9,Data!$A$2:$P$1001, 2, FALSE) -> Dhanush Sinha | C9: =VLOOKUP(A9,Data!$A$2:$P$1001, 8, FALSE) -> West | D9: =VLOOKUP(A9,Data!$A$2:$P$1001, 13, FALSE) -> Mobile
A10: 65201 | B10: =VLOOKUP(A10,Data!$A$2:$P$1001, 2, FALSE) -> Aaradhya Das | C10: =VLOOKUP(A10,Data!$A$2:$P$1001, 8, FALSE) -> West | D10: =VLOOKUP(A10,Data!$A$2:$P$1001, 13, FALSE) -> Mobile
A11: 65202 | B11: =VLOOKUP(A11,Data!$A$2:$P$1001, 2, FALSE) -> Sara Sharma | C11: =VLOOKUP(A11,Data!$A$2:$P$1001, 8, FALSE) -> West | D11: =VLOOKUP(A11,Data!$A$2:$P$1001, 13, FALSE) -> Mobile

Sheet region has highest number of lo

Sheet Average Total Points
A8: {=INDEX(A3:A6, MATCH(MIN(B3:B6), B3:B6, 0))} -> South | B8: =MIN(B3:B6) -> 4207.0656

Sheet Which region has the lowest use
A8: {=INDEX(A2:A5,MATCH(MIN(B2:B5),B2:B5, 0))} -> West | B8: =MIN(B2:B5) -> 192

Sheet Highest Average Streak Count
A7: {=INDEX(A2:A5, MATCH(MAX(B2:B5), B2:B5, 0))} -> East | B7: =MAX(B2:B5) -> 33.468293

Sheet degree category made the lowest
A1: DegreeCategories - DegreeCategoryId → Name | B1: COUNTA of Payment Status
A2: BCA / MCA | B2: 50
A3: BE / BTech - CS / IT | B3: 114
A4: BE / BTech - Non CS / IT | B4: 56
A5: Diploma | B5: 31
A6: Non-Coding, Non Engineering | B6: 76
A7: Grand Total | B7: 327
B8: {=INDEX(A2:A6, MATCH(MIN(B2:B6), B2:B6, 0))} -> Diploma
B9: {=XLOOKUP(MIN(B2:B6), B2:B6, A2:A6)} -> Diploma

Sheet Detail1-Diploma
A1: ID | B1: Names | C1: Gender | D1: Salutation | E1: Proper Name | F1: First Name | G1: Last Name | H1: Region | I1: PassingYear | J1: Price | K1: Payment Status | L1: TotalPoints | M1: Signup Device | N1: Streak | O1: Course Name | P1: DegreeCategories - DegreeCategoryId → Name
A2: 64645 | B2: Mahira Gupta | C2: Female | F2: Mahira | G2: Gupta | H2: North | I2: 2024 | J2: 10000 | K2: Completed | L2: 3622 | M2: Mobile | N2: 8 | O2: Competitive Coding | P2: Diploma
A3: 64741 | B3: Sara Nair | C3: Female | F3: Sara | G3: Nair | H3: East | I3: 2026 | J3: 5000 | K3: Completed | L3: 21084 | M3: Web | N3: 54 | O3: Data Structure and Algorithms | P3: Diploma
A4: 64797 | B4: Avni Bhatt | C4: Female | F4: Avni | G4: Bhatt | H4: North | I4: 2028 | J4: 10000 | K4: Completed | L4: 23905 | M4: Mobile | N4: 51 | O4: Data Structure and Algorithms | P4: Diploma
A5: 64851 | B5: Mishka Singh | C5: Female | F5: Mishka | G5: Singh | H5: South | I5: 2024 | J5: 10000 | K5: Completed | L5: 13137 | M5: Mobile | N5: 55 | O5: Data Structure and Algorithms | P5: Diploma
A6: 64879 | B6: Samarth Kulkarni | C6: Male | F6: Samarth | G6: Kulkarni | H6: South | I6: 2024 | J6: 10000 | K6: Completed | L6: 18887 | M6: Mobile | N6: 65 | O6: Competitive Coding | P6: Diploma
A7: 64905 | B7: Shaurya Singh | C7: Male | F7: Shaurya | G7: Singh | H7: East | I7: 2020 | J7: 5000 | K7: Completed | L7: 2731 | M7: Mobile | N7: 49 | O7: Data Structure and Algorithms | P7: Diploma
A8: 65052 | B8: Kian Chopra | C8: Male | F8: Kian | G8: Chopra | H8: West | I8: 2018 | J8: 5000 | K8: Completed | L8: 14088 | M8: Web | N8: 4 | O8: Competitive Coding | P8: Diploma
A9: 65073 | B9: Prisha Kumar | C9: Female | F9: Prisha | G9: Kumar | H9: South | I9: 2026 | J9: 10000 | K9: Completed | L9: 3733 | M9: Mobile | N9: 22 | O9: Data Structure and Algorithms | P9: Diploma
A10: 65091 | B10: Sai Pillai | C10: Male | F10: Sai | G10: Pillai | H10: North | I10: 2027 | J10: 10000 | K10: Completed | L10: 9611 | M10: Mobile | N10: 4 | O10: Data Structure and Algorithms | P10: Diploma
A11: 65120 | B11: Kabir Patel | C11: Male | F11: Kabir | G11: Patel | H11: North | I11: 2012 | J11: 10000 | K11: Completed | L11: 6129 | M11: Web | N11: 37 | O11: Data Structure and Algorithms | P11: Diploma
A12: 65121 | B12: Riddhi Prasad | C12: Female | F12: Riddhi | G12: Prasad | H12: North | I12: 2023 | J12: 10000 | K12: Completed | L12: 4436 | M12: Mobile | N12: 0 | O12: Data Structure and Algorithms | P12: Diploma
A13: 65125 | B13: Arnav Sharma | C13: Male | F13: Arnav | G13: Sharma | H13: North | I13: 2024 | J13: 10000 | K13: Completed | L13: 15694 | M13: Mobile | N13: 44 | O13: Competitive Coding | P13: Diploma
... A32: 65768 | B32: Saanvi Thakur | C32: Female | F32: Saanvi | G32: Thakur | H32: West | I32: 2023 | J32: 5000 | K32: Completed | L32: 3003 | M32: Mobile | N32: 44 | O32: Competitive Coding | P32: Diploma
